Workbook

Sheet Partner Types
B2: Partner Network — Type Definitions & GTM Impact
B3: Generic B2B SaaS Template
C5: Technology / Ecosystem | D5: Channel / Reseller | E5: Referral Partners | F5: Services / Implementation
B7: Description | C7: Co-sell with complementary platforms. Joint solution positioning. | D7: Partners sell on your behalf under their own or co-branded motion. | E7: Consultants, advisors, former buyers who make warm introductions. Fee per closed deal. | F7: SI firms, consultancies, managed service providers who embed your product into client engagements.
B9: How Leads Enter the Funnel | C9: Enters at SAL — pre-qualified via partner co-sell motion. Skips Lead/MQL. | D9: Partner manages full funnel (Lead to Close) in their market. You see pipeline at Opp stage. | E9: Enters at SQL — warm intro from trusted source. Skips Lead/MQL/SAL. | F9: Enters at Opportunity — SI has already scoped the project. Highest entry point.
B11: Why Conversion Differs from Direct | C11: Partner trust transfers. Buyer has existing relationship with partner platform. Higher SAL>SQL and win rate. | D11: Partner has local/vertical expertise and existing relationships. Win rate slightly above direct. Lower product depth. | E11: Warmest intro in the model. Referrer has direct credibility with buyer. Highest win rate after SI. Shortest cycle. | F11: Buyer has already decided to act. SI is recommending the tool stack. Win rate 50%+ but volume is lowest.
B13: ASP Impact | C13: Neutral to positive. Joint solutions can command premium. List ASP holds or increases 5-10%. | D13: Lower net ASP. Partner takes 20-30% margin. Net to you: 70-80% of list. | E13: ASP holds at direct levels. Referral fee is a fixed % (10-15%), not a margin cut. | F13: Highest ASP. SI projects are larger scope. ASP 1.2-1.5x direct list price.
B15: Cost Structure | C15: Co-marketing spend, partner engineering (integrations), partner manager headcount. Low marginal cost per deal. | D15: Margin share (20-30% of ACV), partner enablement, certification program. Highest per-deal cost but no S&M headcount. | E15: Referral fee (10-15% of first-year ACV). Lowest cost structure. No enablement overhead. | F15: Rev share on implementation (15-20%), joint marketing, technical enablement. Moderate cost, large deals.
B17: Ramp Time | C17: 6-12 months to first co-sell deal. Integration build + joint GTM planning. | D17: 9-18 months to productive partner. Requires training, certification, deal support. | E17: 1-3 months. Fastest to activate. Low friction. | F17: 6-12 months. Requires SI to learn the platform and build a practice around it.
B19: Volume Profile (Yr 3 steady state) | C19: Medium volume. 15-25 deals/yr per active tech partner. | D19: High volume potential. 10-40 deals/yr per productive channel partner. | E19: Low per-referrer but scalable. 2-5 deals/yr per referrer across many referrers. | F19: Low volume, high value. 5-12 deals/yr per SI partner.
B21: Key Risk | C21: Integration maintenance. Partner priorities shift. Co-sell requires ongoing coordination. | D21: Channel conflict with direct sales. Partner may not position product well. Margin compression. | E21: Unpredictable volume. No contractual commitment. Referrers go cold. | F21: Dependency on SI pipeline. Long ramp. SI may substitute competitor if relationship weakens.
B23: ELG / Nearbound Alignment | C23: "Nearbound" motion — leveraging partner ecosystem data and relationships to warm up accounts in your ICP. | D23: Traditional channel — effective when product is packageable and partner has vertical expertise. | E23: Lowest-friction ecosystem play. Ecosystem-Led Growth starts here for most early-stage companies. | F23: "Embed" motion — deepest integration into partner delivery model. Highest lock-in, slowest to build.

Sheet Tech Ecosystem
B2: Technology / Ecosystem Partner Model
B3: Co-sell with complementary platforms — Nearbound motion (ELG framework)
B6: PARTNER PROGRAM ASSUMPTIONS (blue = editable)
B7: Metric | C7: Year 1 | D7: Year 2 | E7: Year 3 | F7: Notes
B8: Active Partners | C8: 2 | D8: 4 | E8: 7 | F8: Y1: 2 integration partners. Y3: 7 active co-sell relationships.
B9: Deals per Partner per Year | C9: 3 | D9: 5 | E9: 8 | F9: Ramps as joint GTM matures
B10: Ramp Factor (% of full productivity) | C10: 0.4 | D10: 0.7 | E10: 0.9 | F10: Y1 is integration build + first co-sell attempts
B11: Effective Partner-Sourced Deals | C11: =ROUND(C8*C9*C10,0) -> 2 | D11: =ROUND(D8*D9*D10,0) -> 14 | E11: =ROUND(E8*E9*E10,0) -> 50 | F11: Partners x Deals/Partner x Ramp
B13: PARTNER FUNNEL METRICS (blue = editable)
H14: Direct Comparison | I14: Delta
B15: Funnel Entry Point | C15: SAL | F15: Partner introduces at SAL.
B16: List / Entry ASP | C16: 90000 | F16: Joint solution commands ~5% premium over direct | H16: 85000 | I16: =C16-H16 -> 5000
B17: Rev Share to Partner | C17: 0.15 | F17: 15% rev share for co-sell sourced deals
B18: Net ASP (after partner cost) | C18: =C16*(1-C17) -> 76500 | F18: What you actually book | H18: 70550 | I18: =C18-H18 -> 5950
B19: Additional Stage Erosion (Opp>Close) | C19: 0.08
B20: Effective Closed ASP (net of all costs) | C20: =C18*(1-C19) -> 70380
B22: CONVERSION & VELOCITY
B23: Stage | C23: Conversion Rate | D23: Days in Stage | F23: Notes | H23: Direct Conv. | I23: Direct Days
B24: SAL > SQL | C24: 0.65 | D24: 10 | F24: Partner trust accelerates qualification | H24: 0.55 | I24: 14
B25: SQL > Opportunity | C25: 0.5 | D25: 18 | F25: Warm intro but still needs your discovery | H25: 0.42 | I25: 21
B26: Opportunity > Closed-Won | C26: 0.38 | D26: 35 | F26: Co-sell support from partner | H26: 0.28 | I26: 45
B28: Cumulative Conversion (Entry > Close) | C28: =C24*C25*C26 -> 0.1235 | H28: =H24*H25*H26 -> 0.06468
B29: Total Sales Cycle (days, entry > close) | D29: =D24+D25+D26 -> 63 | I29: =I24+I25+I26 -> 80
B30: Win Rate (Opp > Close) | C30: =C26 -> 0.38 | H30: =H26 -> 0.28 | I30: =C30-H30 -> 0.1
B32: 3-YEAR PARTNER REVENUE MODEL
B33: Metric | C33: Year 1 | D33: Year 2 | E33: Year 3 | F33: Notes
B34: Partner-Sourced Deals (Closed-Won) | C34: =C11 -> 2 | D34: =D11 -> 14 | E34: =E11 -> 50
B35: Gross Bookings (at List ASP) | C35: =C34*C16 -> 180000 | D35: =D34*C16 -> 1260000 | E35: =E34*C16 -> 4500000
B36: Net Revenue (after partner cost + erosion) | C36: =C34*C20 -> 140760 | D36: =D34*C20 -> 985320 | E36: =E34*C20 -> 3519000 | F36: After partner margin/fee + stage erosion
B37: Partner Cost (Rev Share to Partner) | C37: =C35-C36 -> 39240 | D37: =D35-D36 -> 274680 | E37: =E35-E36 -> 981000
B39: PARTNER CHANNEL CAC (blue = editable)
B40: Cost Category | C40: Year 1 | D40: Year 2 | E40: Year 3 | F40: Notes
B41: Partner Manager Compensation | C41: 0 | D41: 130000 | E41: 140000 | F41: Y1: founder-led. Y2: dedicated partner manager
B42: Integration Engineering & Enablement | C42: 20000 | D42: 45000 | E42: 70000 | F42: API integrations, joint demo environments
B43: Co-Marketing & Partner Events | C43: 5000 | D43: 20000 | E43: 40000
B44: Partner Portal / PRM Tools | C44: 0 | D44: 5000 | E44: 10000
B45: Total Fixed Partner Costs | C45: =SUM(C41:C44) -> 25000 | D45: =SUM(D41:D44) -> 200000 | E45: =SUM(E41:E44) -> 260000 | F45: Spend regardless of deal volume
B46: Variable Partner Cost (Rev Share to Partner) | C46: =C37 -> 39240 | D46: =D37 -> 274680 | E46: =E37 -> 981000 | F46: Per-deal cost from margin/fee
B47: Total All-In Partner Channel Cost | C47: =C45+C46 -> 64240 | D47: =D45+D46 -> 474680 | E47: =E45+E46 -> 1241000
B49: UNIT ECONOMICS — THIS PARTNER TYPE
...

Sheet Channel Reseller
B2: Channel / Reseller Partner Model
B3: Partners sell on your behalf in their market — Traditional channel with margin share
B6: PARTNER PROGRAM ASSUMPTIONS (blue = editable)
B7: Metric | C7: Year 1 | D7: Year 2 | E7: Year 3 | F7: Notes
B8: Active Partners | C8: 1 | D8: 3 | E8: 5 | F8: Y1: 1 pilot reseller. Y3: 5 certified channel partners.
B9: Deals per Partner per Year | C9: 4 | D9: 7 | E9: 11 | F9: Resellers own full cycle. Volume ramps with training.
B10: Ramp Factor (% of full productivity) | C10: 0.25 | D10: 0.6 | E10: 0.85 | F10: Slowest ramp — requires certification and deal support
B11: Effective Partner-Sourced Deals | C11: =ROUND(C8*C9*C10,0) -> 1 | D11: =ROUND(D8*D9*D10,0) -> 13 | E11: =ROUND(E8*E9*E10,0) -> 47 | F11: Partners x Deals/Partner x Ramp
B13: PARTNER FUNNEL METRICS (blue = editable)
H14: Direct Comparison | I14: Delta
B15: Funnel Entry Point | C15: Opportunity (partner-managed) | F15: Partner introduces at Opportunity (partner-managed).
B16: List / Entry ASP | C16: 85000 | F16: List ASP same as direct — partner sells at market rate | H16: 85000 | I16: =C16-H16 -> 0
B17: Channel Margin (% of ACV) | C17: 0.25 | F17: 25% margin to channel partner. Industry standard 20-30%.
B18: Net ASP (after partner cost) | C18: =C16*(1-C17) -> 63750 | F18: What you actually book | H18: 70550 | I18: =C18-H18 -> -6800
B19: Additional Stage Erosion (Opp>Close) | C19: 0.05
B20: Effective Closed ASP (net of all costs) | C20: =C18*(1-C19) -> 60562.5
B22: CONVERSION & VELOCITY
B23: Stage | C23: Conversion Rate | D23: Days in Stage | F23: Notes | H23: Direct Conv. | I23: Direct Days
B24: Partner-Qualified > Opportunity | C24: 0.6 | D24: 14 | F24: Partner qualifies in their process, enters at Opp | H24: 0.42 | I24: 21
B25: Opportunity > Closed-Won | C25: 0.3 | D25: 40 | F25: Partner closes. Slightly above direct — local relationship. | H25: 0.28 | I25: 45
B27: Cumulative Conversion (Entry > Close) | C27: =C24*C25 -> 0.18 | H27: =H24*H25 -> 0.1176
B28: Total Sales Cycle (days, entry > close) | D28: =D24+D25 -> 54 | I28: =I24+I25 -> 66
B29: Win Rate (Opp > Close) | C29: =C25 -> 0.3 | H29: =H25 -> 0.28 | I29: =C29-H29 -> 0.02
B31: 3-YEAR PARTNER REVENUE MODEL
B32: Metric | C32: Year 1 | D32: Year 2 | E32: Year 3 | F32: Notes
B33: Partner-Sourced Deals (Closed-Won) | C33: =C11 -> 1 | D33: =D11 -> 13 | E33: =E11 -> 47
B34: Gross Bookings (at List ASP) | C34: =C33*C16 -> 85000 | D34: =D33*C16 -> 1105000 | E34: =E33*C16 -> 3995000
B35: Net Revenue (after partner cost + erosion) | C35: =C33*C20 -> 60562.5 | D35: =D33*C20 -> 787312.5 | E35: =E33*C20 -> 2846437.5 | F35: After partner margin/fee + stage erosion
B36: Partner Cost (Channel Margin (% of ACV)) | C36: =C34-C35 -> 24437.5 | D36: =D34-D35 -> 317687.5 | E36: =E34-E35 -> 1148562.5
B38: PARTNER CHANNEL CAC (blue = editable)
B39: Cost Category | C39: Year 1 | D39: Year 2 | E39: Year 3 | F39: Notes
B40: Partner Manager Compensation | C40: 0 | D40: 130000 | E40: 260000 | F40: Y1: founder-led. Y3: 2 channel managers
B41: Partner Certification & Training | C41: 12000 | D41: 35000 | E41: 70000 | F41: Onboarding, sales playbooks, demo environments
B42: Co-Marketing & Partner Events | C42: 5000 | D42: 18000 | E42: 35000
B43: Partner Portal / PRM Tools | C43: 0 | D43: 10000 | E43: 15000
B44: Total Fixed Partner Costs | C44: =SUM(C40:C43) -> 17000 | D44: =SUM(D40:D43) -> 193000 | E44: =SUM(E40:E43) -> 380000 | F44: Spend regardless of deal volume
B45: Variable Partner Cost (Channel Margin (% of ACV)) | C45: =C36 -> 24437.5 | D45: =D36 -> 317687.5 | E45: =E36 -> 1148562.5 | F45: Per-deal cost from margin/fee
B46: Total All-In Partner Channel Cost | C46: =C44+C45 -> 41437.5 | D46: =D44+D45 -> 510687.5 | E46: =E44+E45 -> 1528562.5
B48: UNIT ECONOMICS — THIS PARTNER TYPE
B49: Metric | C49: Year 1 | D49: Year 2 | E49: Year 3 | H49: Direct CAC | I49: Delta
...

Sheet Referral
B2: Referral Partner Model
B3: Advisors, consultants, former buyers making warm introductions — Lowest friction ELG entry point
B6: PARTNER PROGRAM ASSUMPTIONS (blue = editable)
B7: Metric | C7: Year 1 | D7: Year 2 | E7: Year 3 | F7: Notes
B8: Active Partners | C8: 6 | D8: 15 | E8: 30 | F8: Y1: advisory network + early customers. Y3: 30 active referrers.
B9: Deals per Partner per Year | C9: 1.5 | D9: 2 | E9: 2.5 | F9: Low per-person but scales with referrer count
B10: Ramp Factor (% of full productivity) | C10: 0.5 | D10: 0.75 | E10: 0.9 | F10: Fastest ramp — warm intros start within weeks
B11: Effective Partner-Sourced Deals | C11: =ROUND(C8*C9*C10,0) -> 5 | D11: =ROUND(D8*D9*D10,0) -> 23 | E11: =ROUND(E8*E9*E10,0) -> 68 | F11: Partners x Deals/Partner x Ramp
B13: PARTNER FUNNEL METRICS (blue = editable)
H14: Direct Comparison | I14: Delta
B15: Funnel Entry Point | C15: SQL | F15: Partner introduces at SQL.
B16: List / Entry ASP | C16: 85000 | F16: Same as direct — referral doesn't affect pricing | H16: 85000 | I16: =C16-H16 -> 0
B17: Referral Fee (% of 1st Year ACV) | C17: 0.1 | F17: 10% of first-year ACV. Paid on close. Industry 10-15%.
B18: Net ASP (after partner cost) | C18: =C16*(1-C17) -> 76500 | F18: What you actually book | H18: 70550 | I18: =C18-H18 -> 5950
B19: Additional Stage Erosion (Opp>Close) | C19: 0.05
B20: Effective Closed ASP (net of all costs) | C20: =C18*(1-C19) -> 72675
B22: CONVERSION & VELOCITY
B23: Stage | C23: Conversion Rate | D23: Days in Stage | F23: Notes | H23: Direct Conv. | I23: Direct Days
B24: SQL > Opportunity | C24: 0.55 | D24: 14 | F24: Referred buyer is pre-disposed. Less convincing needed. | H24: 0.42 | I24: 21
B25: Opportunity > Closed-Won | C25: 0.4 | D25: 30 | F25: Highest win rate — referrer credibility carries through close. | H25: 0.28 | I25: 45
B27: Cumulative Conversion (Entry > Close) | C27: =C24*C25 -> 0.22 | H27: =H24*H25 -> 0.1176
B28: Total Sales Cycle (days, entry > close) | D28: =D24+D25 -> 44 | I28: =I24+I25 -> 66
B29: Win Rate (Opp > Close) | C29: =C25 -> 0.4 | H29: =H25 -> 0.28 | I29: =C29-H29 -> 0.12
B31: 3-YEAR PARTNER REVENUE MODEL
B32: Metric | C32: Year 1 | D32: Year 2 | E32: Year 3 | F32: Notes
B33: Partner-Sourced Deals (Closed-Won) | C33: =C11 -> 5 | D33: =D11 -> 23 | E33: =E11 -> 68
B34: Gross Bookings (at List ASP) | C34: =C33*C16 -> 425000 | D34: =D33*C16 -> 1955000 | E34: =E33*C16 -> 5780000
B35: Net Revenue (after partner cost + erosion) | C35: =C33*C20 -> 363375 | D35: =D33*C20 -> 1671525 | E35: =E33*C20 -> 4941900 | F35: After partner margin/fee + stage erosion
B36: Partner Cost (Referral Fee (% of 1st Year ACV)) | C36: =C34-C35 -> 61625 | D36: =D34-D35 -> 283475 | E36: =E34-E35 -> 838100
B38: PARTNER CHANNEL CAC (blue = editable)
B39: Cost Category | C39: Year 1 | D39: Year 2 | E39: Year 3 | F39: Notes
B40: Partner Manager Compensation | C40: 0 | D40: 0 | E40: 65000 | F40: Y1-2: founder-managed. Y3: part-time coordinator.
B41: Referral Program Setup & Materials | C41: 4000 | D41: 8000 | E41: 12000 | F41: One-pagers, referral portal, tracking system
B42: Co-Marketing & Partner Events | C42: 2000 | D42: 5000 | E42: 8000
B43: Partner Portal / PRM Tools | C43: 0 | D43: 2500 | E43: 5000
B44: Total Fixed Partner Costs | C44: =SUM(C40:C43) -> 6000 | D44: =SUM(D40:D43) -> 15500 | E44: =SUM(E40:E43) -> 90000 | F44: Spend regardless of deal volume
B45: Variable Partner Cost (Referral Fee (% of 1st Year ACV)) | C45: =C36 -> 61625 | D45: =D36 -> 283475 | E45: =E36 -> 838100 | F45: Per-deal cost from margin/fee
B46: Total All-In Partner Channel Cost | C46: =C44+C45 -> 67625 | D46: =D44+D45 -> 298975 | E46: =E44+E45 -> 928100
B48: UNIT ECONOMICS — THIS PARTNER TYPE
B49: Metric | C49: Year 1 | D49: Year 2 | E49: Year 3 | H49: Direct CAC | I49: Delta
...

Sheet Services SI
B2: Services / Implementation Partner Model
B3: SI firms and consultancies embedding your product into client engagements — Deepest ecosystem integration
B6: PARTNER PROGRAM ASSUMPTIONS (blue = editable)
B7: Metric | C7: Year 1 | D7: Year 2 | E7: Year 3 | F7: Notes
B8: Active Partners | C8: 1 | D8: 2 | E8: 4 | F8: Y1: 1 boutique SI. Y3: 4 including 1-2 mid-tier firms.
B9: Deals per Partner per Year | C9: 3 | D9: 5 | E9: 7 | F9: SI pipeline is lumpy — large projects with long cycles
B10: Ramp Factor (% of full productivity) | C10: 0.3 | D10: 0.65 | E10: 0.85 | F10: SI must build practice around product. Slow start, strong finish.
B11: Effective Partner-Sourced Deals | C11: =ROUND(C8*C9*C10,0) -> 1 | D11: =ROUND(D8*D9*D10,0) -> 7 | E11: =ROUND(E8*E9*E10,0) -> 24 | F11: Partners x Deals/Partner x Ramp
B13: PARTNER FUNNEL METRICS (blue = editable)
H14: Direct Comparison | I14: Delta
B15: Funnel Entry Point | C15: Opportunity | F15: Partner introduces at Opportunity.
B16: List / Entry ASP | C16: 120000 | F16: SI projects are larger scope. 1.3-1.5x direct ASP. | H16: 85000 | I16: =C16-H16 -> 35000
B17: Implementation Rev Share | C17: 0.18 | F17: 18% rev share on software. SI keeps services revenue separately.
B18: Net ASP (after partner cost) | C18: =C16*(1-C17) -> 98400 | F18: What you actually book | H18: 70550 | I18: =C18-H18 -> 27850
B19: Additional Stage Erosion (Opp>Close) | C19: 0.05
B20: Effective Closed ASP (net of all costs) | C20: =C18*(1-C19) -> 93480
B22: CONVERSION & VELOCITY
B23: Stage | C23: Conversion Rate | D23: Days in Stage | F23: Notes | H23: Direct Conv. | I23: Direct Days
B24: SI-Qualified Opp > Closed-Won | C24: 0.5 | D24: 40 | F24: Highest win rate — SI has pre-sold and scoped. | H24: 0.28 | I24: 45
B26: Cumulative Conversion (Entry > Close) | C26: =C24 -> 0.5 | H26: =H24 -> 0.28
B27: Total Sales Cycle (days, entry > close) | D27: =D24 -> 40 | I27: =I24 -> 45
B28: Win Rate (Opp > Close) | C28: =C24 -> 0.5 | H28: =H24 -> 0.28 | I28: =C28-H28 -> 0.22
B30: 3-YEAR PARTNER REVENUE MODEL
B31: Metric | C31: Year 1 | D31: Year 2 | E31: Year 3 | F31: Notes
B32: Partner-Sourced Deals (Closed-Won) | C32: =C11 -> 1 | D32: =D11 -> 7 | E32: =E11 -> 24
B33: Gross Bookings (at List ASP) | C33: =C32*C16 -> 120000 | D33: =D32*C16 -> 840000 | E33: =E32*C16 -> 2880000
B34: Net Revenue (after partner cost + erosion) | C34: =C32*C20 -> 93480 | D34: =D32*C20 -> 654360 | E34: =E32*C20 -> 2243520 | F34: After partner margin/fee + stage erosion
B35: Partner Cost (Implementation Rev Share) | C35: =C33-C34 -> 26520 | D35: =D33-D34 -> 185640 | E35: =E33-E34 -> 636480
B37: PARTNER CHANNEL CAC (blue = editable)
B38: Cost Category | C38: Year 1 | D38: Year 2 | E38: Year 3 | F38: Notes
B39: Partner Manager Compensation | C39: 0 | D39: 130000 | E39: 140000 | F39: Y1: founder-led. Y2: dedicated SI partner manager.
B40: SI Enablement & Technical Training | C40: 18000 | D40: 50000 | E40: 90000 | F40: Deep technical training, certification, sandbox environments
B41: Co-Marketing & Partner Events | C41: 5000 | D41: 12000 | E41: 25000
B42: Partner Portal / PRM Tools | C42: 0 | D42: 5000 | E42: 10000
B43: Total Fixed Partner Costs | C43: =SUM(C39:C42) -> 23000 | D43: =SUM(D39:D42) -> 197000 | E43: =SUM(E39:E42) -> 265000 | F43: Spend regardless of deal volume
B44: Variable Partner Cost (Implementation Rev Share) | C44: =C35 -> 26520 | D44: =D35 -> 185640 | E44: =E35 -> 636480 | F44: Per-deal cost from margin/fee
B45: Total All-In Partner Channel Cost | C45: =C43+C44 -> 49520 | D45: =D43+D44 -> 382640 | E45: =E43+E44 -> 901480
B47: UNIT ECONOMICS — THIS PARTNER TYPE
B48: Metric | C48: Year 1 | D48: Year 2 | E48: Year 3 | H48: Direct CAC | I48: Delta
B49: Partner Channel CAC (all-in / deal) | C49: =IF(C32=0,0,C45/C32) -> 49520 | D49: =IF(D32=0,0,D45/D32) -> 54662.857 | E49: =IF(E32=0,0,E45/E32) -> 37561.667 | H49: ='Revenue Model'!C42 -> 15000 | I49: =C49-H49 -> 34520
...

Sheet Comparison Summary
B2: Partner Channel Comparison — 3-Year Summary
B3: All figures reference editable inputs on individual partner tabs
B6: Metric | C6: Direct (baseline) | D6: Tech / Ecosystem | E6: Channel / Reseller | F6: Referral | G6: Services / SI
B7: FUNNEL CHARACTERISTICS
B8: Entry Point | C8: Lead | D8: ='Tech Ecosystem'!C15 -> SAL | E8: ='Channel Reseller'!C15 -> Opportunity (partner-managed) | F8: =Referral!C15 -> SQL | G8: ='Services SI'!C15 -> Opportunity
B9: List / Entry ASP | C9: 85000 | D9: ='Tech Ecosystem'!C16 -> 90000 | E9: ='Channel Reseller'!C16 -> 85000 | F9: =Referral!C16 -> 85000 | G9: ='Services SI'!C16 -> 120000
B10: Net ASP | C10: 70550 | D10: ='Tech Ecosystem'!C18 -> 76500 | E10: ='Channel Reseller'!C18 -> 63750 | F10: =Referral!C18 -> 76500 | G10: ='Services SI'!C18 -> 98400
B11: Partner Cost % | C11: — | D11: ='Tech Ecosystem'!C17 -> 0.15 | E11: ='Channel Reseller'!C17 -> 0.25 | F11: =Referral!C17 -> 0.1 | G11: ='Services SI'!C17 -> 0.18
B12: Win Rate (Opp > Close) | C12: 0.25 | D12: ='Tech Ecosystem'!C30 -> 0.38 | E12: ='Channel Reseller'!C29 -> 0.3 | F12: =Referral!C29 -> 0.4 | G12: ='Services SI'!C28 -> 0.5
B14: YEAR 3 VOLUME & REVENUE (steady state)
B15: Active Partners | D15: ='Tech Ecosystem'!E8 -> 7 | E15: ='Channel Reseller'!E8 -> 5 | F15: =Referral!E8 -> 30 | G15: ='Services SI'!E8 -> 4
B16: Y3 Closed-Won Deals | C16: 60 | D16: ='Tech Ecosystem'!E11 -> 50 | E16: ='Channel Reseller'!E11 -> 47 | F16: =Referral!E11 -> 68 | G16: ='Services SI'!E11 -> 24
B17: Y3 Net Revenue | C17: — | D17: ='Tech Ecosystem'!E36 -> 3519000 | E17: ='Channel Reseller'!E35 -> 2846437.5 | F17: =Referral!E35 -> 4941900 | G17: ='Services SI'!E34 -> 2243520
B18: TOTAL Partner Deals (Y3) | D18: =SUM(D16:G16) -> 189
B19: TOTAL Partner Net Revenue (Y3) | D19: =SUM(D17:G17) -> 13550858
B21: YEAR 3 UNIT ECONOMICS COMPARISON
B22: Partner CAC (Y3, all-in / deal) | C22: ='Revenue Model'!E38 -> 15000 | D22: ='Tech Ecosystem'!E51 -> 24820 | E22: ='Channel Reseller'!E50 -> 32522.606 | F22: =Referral!E50 -> 13648.529 | G22: ='Services SI'!E49 -> 37561.667
B23: CAC as % of Net ASP | C23: =IF(C10=0,0,C22/C10) -> 0.21261517 | D23: ='Tech Ecosystem'!E52 -> 0.32444444 | E23: ='Channel Reseller'!E51 -> 0.51015853 | F23: =Referral!E51 -> 0.17841215 | G23: ='Services SI'!E50 -> 0.38172425
B24: CAC Payback (months) | C24: =C23*12 -> 2.551382 | D24: ='Tech Ecosystem'!E53 -> 3.8933333 | E24: ='Channel Reseller'!E52 -> 6.1219024 | F24: =Referral!E52 -> 2.1409458 | G24: ='Services SI'!E51 -> 4.5806911
B25: Revenue per $1 Partner Spend | C25: — | D25: ='Tech Ecosystem'!E54 -> 2.8356164 | E25: ='Channel Reseller'!E53 -> 1.8621663 | F25: =Referral!E53 -> 5.3247495 | G25: ='Services SI'!E52 -> 2.4887075
B27: STRATEGIC FIT
B28: Time to First Deal | C28: — | D28: 6-12 months | E28: 9-18 months | F28: 1-3 months | G28: 6-12 months
B29: Volume Potential (Y3) | C29: — | D29: Medium (15-25/partner) | E29: High (10-40/partner) | F29: Low (2-5/referrer) | G29: Low (5-12/partner)
B30: ASP Impact | C30: Baseline | D30: Positive (+5-10%) | E30: Neutral (margin drag) | F30: Neutral | G30: Positive (+30-50%)
B31: ELG Readiness (start here?) | C31: — | D31: Phase 2 | E31: Phase 3 | F31: Phase 1 — START HERE | G31: Phase 2-3
B32: Recommended Priority | C32: — | D32: 2nd | E32: 3rd | F32: 1st | G32: 2nd (if right SI exists)

Sheet Revenue Model
B2: Sales Stage Metrics Calculator
B3: Direct Baseline — Generic B2B SaaS
C5: Lead / Prospect | D5: MQL | E5: SAL | F5: SQL | G5: Opportunity | H5: Closed-Won
B6: VALUE, TIME & CONVERSION INPUTS (blue = editable)
B7: List / Entry ASP | C7: — | D7: — | E7: 85000 | F7: =E7*(1-F8) -> 80750 | G7: =F7*(1-G8) -> 74290 | H7: =G7*(1-H8) -> 70575.5
B8: Discount / Erosion Rate (per stage) | C8: — | D8: — | E8: — | F8: 0.05 | G8: 0.08 | H8: 0.05
B10: Velocity (Avg Days in Stage) | C10: 5 | D10: 7 | E10: 14 | F10: 21 | G10: 45 | H10: —
B11: Conversion Rate (Stage > Next) | C11: 0.35 | D11: 0.45 | E11: 0.55 | F11: 0.42 | G11: 0.25 | H11: —
B12: Win Rate (Opp > Closed-Won) | G12: =G11 -> 0.25
B14: CALCULATED METRICS
B15: Total Sales Cycle (Lead > Close, Days) | C15: =SUM(C10:G10) -> 92
B16: Cumulative Conversion (Lead > Close) | C16: =C11*D11*E11*F11*G11 -> 0.009095625
B17: Leads Needed per Closed Deal | C17: =IF(C16=0,0,ROUND(1/C16,0)) -> 110
B19: REVENUE TARGET SCENARIO (blue = editable)
B20: Annual Revenue Target | C20: 2500000
B21: Closed-Won Deals Needed | C21: =IF(H7=0,0,ROUND(C20/H7,0)) -> 35
B22: Leads Needed | C22: =C21*C17 -> 3850
B23: Monthly Lead Generation Required | C23: =ROUND(C22/12,0) -> 321
B25: IMPACT ANALYSIS — Revenue lift from +5 point improvement
E26: Current | F26: Improved | G26: New Revenue | H26: Lift
B27: Baseline | G27: =C21*H7 -> 2470142.5
B28: +5 pts Win Rate | E28: 0.25 | F28: 0.3 | G28: =ROUND(C20/(E7*(1-F8)*(1-G8)*(1-H8)*F28)*F28*(E7*(1-F8)*(1-G8)*(1-H8)),0) -> 2500000 | H28: =G28-G27 -> 29857.5
B31: DIRECT S&M COST SUMMARY (blue = editable)
C32: Year 1 | D32: Year 2 | E32: Year 3
B33: Total S&M Spend | C33: 150000 | D33: 500000 | E33: 900000 | F33: All-in: people + tools + marketing + partner fees
B34: Closed-Won Deals | C34: 20 | D34: 40 | E34: 60
B36: DIRECT CAC
C37: Year 1 | D37: Year 2 | E37: Year 3 | F37: Benchmark
B38: CAC (per deal) | C38: =IF(C34=0,0,C33/C34) -> 7500 | D38: =IF(D34=0,0,D33/D34) -> 12500 | E38: =IF(E34=0,0,E33/E34) -> 15000
B39: CAC as % of First-Year ACV | C39: =IF(H7=0,0,C38/H7) -> 0.10626917 | D39: =IF(H7=0,0,D38/H7) -> 0.17711529 | E39: =IF(H7=0,0,E38/H7) -> 0.21253835 | F39: Target: <40% midmarket SaaS
B40: CAC Payback (months) | C40: =C39*12 -> 1.2752301 | D40: =D39*12 -> 2.1253835 | E40: =E39*12 -> 2.5504601 | F40: Target: <18mo. Best: <12mo
B42: Y3 Direct CAC (reference for partner tabs) | C42: =E38 -> 15000

Sheet Post-Sale & Expansion
B2: Post-Sale & Expansion Model (Right Side of Bowtie)
B3: Onboarding > Adoption > Renewal > Expansion
C5: Onboarding | D5: First Value | E5: Adopted | F5: Renewal | G5: Expansion
B6: POST-SALE INPUTS (blue = editable)
B7: Time in Stage (days) | C7: 45 | D7: 30 | E7: 90 | F7: 30 | G7: 60
B8: Stage Success Rate | C8: 0.9 | D8: 0.85 | E8: 0.8 | F8: 0.88 | G8: 0.3
B10: RETENTION & EXPANSION METRICS
B11: Time to First Value (TTFV) in Days | C11: =C7+D7 -> 75 | F11: Onboarding + First Value combined
B12: Gross Retention Rate (GRR) | C12: =C8*D8*E8*F8 -> 0.53856 | F12: Probability customer reaches renewal and renews
B13: Logo Retention Rate | C13: =F8 -> 0.88 | F13: Simple renewal rate at contract decision point
B14: Expansion Attach Rate | C14: =G8 -> 0.3
B15: Net Revenue Retention (NRR) | C15: =C12+(C14*C20/C18) -> 0.5895692 | F15: GRR + expansion revenue contribution
B17: EXPANSION REVENUE MODEL (blue = editable)
B18: Initial Contract Value (from left side) | C18: ='Revenue Model'!H7 -> 70575.5
B19: Avg Expansion Deal Value [PLACEHOLDER] | C19: 40000
B20: Expansion Revenue per Customer | C20: =C19*C14 -> 12000
B22: EXPANSION LANES [PLACEHOLDER VALUES — TBD PENDING PRICING]
C23: Avg Deal Size | D23: Attach Rate | E23: Trigger Signal | F23: Typical Timing
B24: Additional Use Cases / Modules | C24: 45000 | D24: 0.2 | E24: Customer completes first use case successfully; mentions adjacent problems | F24: Month 4-6 post-onboarding
B25: Deeper Integration | C25: 30000 | D25: 0.25 | E25: Data quality issues surface; customer asks about connecting additional sources | F25: Month 3-4 post-first-value
B26: Managed Services Layer | C26: 55000 | D26: 0.12 | E26: Customer lacks internal team; support ticket volume increases | F26: Month 6-12 post-adoption
B28: CUSTOMER LIFETIME VALUE
B29: Expected Customer Lifetime (years) | C29: 3
B30: Year 1 Revenue (initial contract) | C30: =C18 -> 70575.5
B31: Year 1 Expansion Revenue | C31: =C20 -> 12000
B32: Annual Renewal Revenue (Yr 2+) | C32: =C18*C13 -> 62106.44
B33: Annual Expansion Revenue (Yr 2+) | C33: =C20 -> 12000
B35: Customer Lifetime Value [PLACEHOLDER] | C35: =C30+C31+(C32+C33)*(C29-1) -> 230788.38 | F35: Derived from placeholder expansion values
